Workbook
Name chfeur_exit: 'NBs List'!$P$5
Name chfeur_offer: 'Exchange Offer'!$B$4
Name chfusd_exit: 'NBs List'!$P$4
Name chfusd_offer: 'Exchange Offer'!$B$3
Name ds_oldbonds_123: #REF!
Name ds_oldbonds_data: #REF!
Name eurusd_exit: 'NBs List'!$P$3
Name eurusd_offer: 'Exchange Offer'!$B$2
Name exit_newbonds: 'NBs List'!$A$3:$A$14
Name exit_prices: 'NBs List'!$M$3:$M$14
Name exit_yields: 'NBs List'!$N$3:$N$14
Name key_date: #REF!
Name new_bond_ref: #REF!
Name NPVs_oldbonds_durations: 'EBs NPVs'!$E$121:$E$145
Name NPVs_oldbonds_names: 'EBs NPVs'!$A$121:$A$145
Name NPVs_oldbonds_vals: 'EBs NPVs'!$F$121:$F$145
Name offer_adj_newbonds: 'Exchange Offer'!$D$37:$O$37
Name offer_adj_notender_newbonds: 'Exchange Offer'!$Q$37:$AB$37
Name offer_adj_notender_vals: 'Exchange Offer'!$Q$38:$AB$62
Name offer_adj_oldbonds: 'Exchange Offer'!$A$38:$A$62
Name offer_adj_oldbonds_alt: 'Exchange Offer'!$C$38:$C$62
Name offer_adj_vals: 'Exchange Offer'!$D$38:$O$62
Name offer_raw_newbonds: 'Exchange Offer'!$D$8:$O$8
Name offer_raw_oldbonds: 'Exchange Offer'!$A$9:$A$33
Name offer_raw_vals: 'Exchange Offer'!$D$9:$O$33
Name old_bond_ref: #REF!
Name OldBonds: #REF!
Name oldbonds_prices_dates: #REF!
Name oldbonds_prices_names: #REF!
Name oldbonds_prices_vals: #REF!
Name orders_afterAPPs_newbonds: 'Exchange Results'!$AM$3:$AV$3
Name orders_afterAPPs_vals: 'Exchange Results'!$AM$4:$AV$28
Name orders_beforeAPPs_newbonds: 'Exchange Results'!$AC$3:$AL$3
Name orders_beforeAPPs_vals: 'Exchange Results'!$AC$4:$AL$28
Name orders_oldbonds: 'Exchange Results'!$A$4:$A$28
Name results_names: 'Exchange Results'!$C$3:$C$28
Name results_vals: 'Exchange Results'!$C$3:$AV$28
Name RRs_adj_oldbonds: 'Exchange Results'!$A$64:$A$88
Name RRs_mkt_newbonds: 'Exchange Results'!$D$32:$M$32
Name RRs_mkt_vals: 'Exchange Results'!$D$33:$M$57
Name RRs_mktadj_newbonds: 'Exchange Results'!$D$63:$M$63
Name RRs_mktadj_vals: 'Exchange Results'!$D$64:$M$88
Name RRs_oldbonds: 'Exchange Results'!$A$33:$A$57
Name RRs_sz_newbonds: 'Exchange Results'!$R$32:$AA$32
Name RRs_sz_vals: 'Exchange Results'!$R$33:$AA$57
Name RRs_szadj_newbonds: 'Exchange Results'!$N$63:$W$63
Name RRs_szadj_vals: 'Exchange Results'!$N$64:$W$88

Sheet README
A1: Companion Spreadsheet for
A2: "Majority Voting in Sovereign Restructurings: The Aggregation Dilemma"
A3: by Carlo Galli and Stephane Guibaud
A5: Abbreviations
A6: EB | B6: Eligible Bonds
A7: NB | B7: New Bonds
A8: NPV | B8: Net Present Value
A9: PA | B9: Principal Amount
A10: FV | B10: Face Value
A13: List of Sheets | B13: Description
A14: EBs List | B14: Details on Kirchner and Macri EBs
A15: Kirchner EBs Cashflows | B15: Detailed cashflows, principal capitalization, and amortization structures of the Kirchner bonds
A16: EBs NPVs | B16: NPV and duration calculations for the EBs
A17: EBs Prices | B17: Historical prices and yields of the EBs. Source: LSEG Workspace
A18: Exchange Offer | B18: Details on the exchange conversion rates
A19: Exchange Results | B19: Details on the exchange recovery rates
... A22: NBs Prices | B22: Historical prices and yields of the NBs. Source: LSEG Workspace
A26: Notes regarding Kirchner "Discount" Bonds
A27: - We denote by "Effective FV" the actual capitalised notional as of the exchange offer date (i.e., approx 140 USD and 138 EUR), and by the "Nominal" FV the theoretical notional that would appear in the Bond Prospectus at issuance.
A28: - In the "Exhange Results" sheet, the Tendered Amounts must be multiplied by the Effective/Nominal FV ratio (approx 1.4) in order to reconcile the quantities with the "PA that consented" column.
A29: - In the "EBs List" and "Exchange Results" sheets, the PA outstanding is measured in Effective FV (i.e. if there was 1 bond outstanding, the PA outsanding would be approx 140 USD or 138 EUR).
A30: - In the "Exchange Offer" sheet, the offers are expressed in Nominal FV (i.e. 100), so we adjust them using the Effective/Nominal FV ratio.
A31: - In the "EBs Prices" sheet, we assume that the historical bond prices from LSEG Workspace are per 100 USD of Effective FV.
A32: - In the "EBs List" sheet, coupon rates are abusted by the Effective/Nominal FV ratio.
A34: Other Notes
A35: - In the "Exchange Results" sheet, "PA that consented" = "Sum of Tender Orders" - " PA controlled by Argentina", and "Consent share" = "PA that consented" / "PA Outstanding"

Sheet EBs List
A1: Lookup name | B1: Short Name | C1: Bond Description (Exchange Offer terminology) | D1: Defined Term (Exchange Offer Terminology) | E1: Indenture | F1: Issue date | G1: ISIN (SEC) | H1: ISIN (Reg S) | I1: ISIN (144A) | J1: Coupon rate | K1: Coupon Frequency (months) | L1: Maturity date | M1: Amortization terms | N1: Total PA outstanding | O1: PA controlled by ARG | P1: Effective Face Value on Valuation Date
A2: USD 2033 Discount I | B2: USD 2033 Discount I | C2: U.S. dollar-denominated Discounts due 2033 (New York law) issued in 2005 (the “USD 2033 Discount Bonds I”) | D2: USD Discount Bonds | E2: 2005 | F2: 38626 | G2: US040114GL81 | J2: 0.0828 | K2: =ROUND(('EBs NPVs'!E9-'EBs NPVs'!D9)/30,0) -> 6 | L2: 48944 | M2: twenty equal semi-annual payments on June 30 and December 31 of each year,commencing on June 30, 2024 | N2: 3857694.7 | O2: 403847.7 | P2: ='Kirchner EBs Cashflows'!$AI$5 -> 140.20421
A3: USD 2033 Discount II and III | B3: USD 2033 Discount II | C3: U.S. dollar-denominated Discounts due 2033 (New York law) issued in 2010 (the “USD 2033 Discount Bonds II”) | D3: USD Discount Bonds | E3: 2005 | F3: 40296 | G3: XS0501194756 | J3: 0.0828 | K3: =ROUND(('EBs NPVs'!E10-'EBs NPVs'!D10)/30,0) -> 6 | L3: 48944 | M3: twenty equal semi-annual payments on June 30 and December 31 of each year,commencing on June 30, 2024 | N3: 1242697.5 | O3: 68982.757 | P3: ='Kirchner EBs Cashflows'!$AI$5 -> 140.20421
A4: USD Par 2038 I | B4: USD Par 2038 I | C4: U.S. dollar-denominated Pars due 2038 (New York law) issued in 2005 (the “USD Par 2038 Bonds I”) | D4: USD Par Bonds | E4: 2005 | F4: 38626 | G4: US040114GK09 | J4: 1.33% to 3/31/2009; 2.5% to 3/31/2019; 3.75% to 3/31/2029; 5.25% to 12/31/2038 | K4: =ROUND(('EBs NPVs'!E11-'EBs NPVs'!D11)/30,0) -> 6 | L4: 50770 | M4: twenty equal semi-annual payments; the first nineteen installments on March 31 and September 30 of each year, commencing on September 30, 2029, and will pay the last installment on December 31, 2038 | N4: 4938659.9 | O4: 358029.25 | P4: 100
A5: USD Par 2038 II and III | B5: USD Par 2038 II and III | C5: U.S. dollar-denominated Pars due 2038 (New York law) issued in 2010 (the “USD Par 2038 Bonds II”) | D5: USD Par Bonds | E5: 2005 | F5: 40296 | G5: XS0501195647 | J5: 2.5% to 3/31/2019; 3.75% to 3/31/2029; 5.25% to 12/31/2038 | K5: =ROUND(('EBs NPVs'!E12-'EBs NPVs'!D12)/30,0) -> 6 | L5: 50770 | M5: twenty equal semi-annual payments; the first nineteen installments on March 31 and September 30 of each year, commencing on September 30, 2029, and will pay the last installment on December 31, 2038 | N5: 94939.179 | O5: 0 | P5: 100
A6: Euro 2033 Discount I | B6: Euro 2033 Discount I | C6: Euro-denominated Discounts due 2033 (English law) issued in 2005 (the “Euro 2033 Discount Bonds I”) | D6: Euro Discount Bonds | E6: 2005 | F6: 38626 | G6: XS0205545840 | J6: 0.0782 | K6: =ROUND(('EBs NPVs'!E13-'EBs NPVs'!D13)/30,0) -> 6 | L6: 48944 | M6: twenty equal semi-annual payments on June 30 and December 31 of each year, commencing on June 30, 2024 | N6: 3107582.4 | O6: 7241.919 | P6: ='Kirchner EBs Cashflows'!$AK$23 -> 137.96394
A7: Euro 2033 Discount II and III | B7: Euro 2033 Discount II and III | C7: Euro-denominated Discounts due 2033 (English law) issued in 2010 (the “Euro 2033 Discount Bonds II”) | D7: Euro Discount Bonds | E7: 2005 | F7: 40350 | G7: XS0501195134 | J7: 0.0782 | K7: =ROUND(('EBs NPVs'!E14-'EBs NPVs'!D14)/30,0) -> 6 | L7: 48944 | M7: twenty equal semi-annual payments on June 30 and December 31 of each year, commencing on June 30, 2024 | N7: 2661472.4 | O7: 0 | P7: ='Kirchner EBs Cashflows'!$AK$23 -> 137.96394
A8: Euro Par 2038 I | B8: Euro Par 2038 I | C8: Euro-denominated Pars due 2038 (English law) issued in 2005 (the “Euro Par 2038 Bonds I”) | D8: Euro Par Bonds | E8: 2005 | F8: 38626 | G8: XS0205537581 | J8: 1.2% to 3/31/2009; 2.26% to 3/31/2019; 3.38% to 3/31/2029; 4.74% to 12/31/2038 | K8: =ROUND(('EBs NPVs'!E15-'EBs NPVs'!D15)/30,0) -> 6 | L8: 50770 | M8: twenty equal semi-annual payments; the first nineteen installments on March 31 and September 30 of each year, commencing on September 30, 2029, and will pay the last installment on December 31, 2038 | N8: 5034912.2 | O8: 0 | P8: 100
A9: Euro Par 2038 II and III | B9: Euro Par 2038 II and III | C9: Euro-denominated Pars due 2038 (English law) issued in 2010 (the “Euro Par 2038 Bonds II”) | D9: Euro Par Bonds | E9: 2005 | F9: 40296 | G9: XS0501195993 | J9: 2.26% to 3/31/2019; 3.38% to 3/31/2029; 4.74% to 12/31/2038 | K9: =ROUND(('EBs NPVs'!E16-'EBs NPVs'!D16)/30,0) -> 6 | L9: 50770 | M9: twenty equal semi-annual payments; the first nineteen installments on March 31 and September 30 of each year, commencing on September 30, 2029, and will pay the last installment on December 31, 2038 | N9: 1438310.9 | O9: 0 | P9: 100
A10: USD 2021 | B10: USD 2021 | C10: U.S. dollar-denominated 6.875 per cent. International Bonds due 2021 (the “USD 2021 Bonds”) | D10: USD Bonds due 2021-2023 | E10: 2016 | F10: 42482 | G10: US040114GW47 | H10: USP04808AA23 | J10: 0.06875 | K10: =ROUND(('EBs NPVs'!E17-'EBs NPVs'!D17)/30,0) -> 6 | L10: 44308 | M10: bullet | N10: 4484000 | O10: 16000 | P10: 100
A11: USD 2022 | B11: USD 2022 | C11: U.S. dollar-denominated 5.625 per cent. International Bonds due 2022 (the “USD 2022 Bonds”) | D11: USD Bonds due 2021-2023 | E11: 2016 | F11: 42761 | G11: US040114HK99 | H11: USP04808AL87 | J11: 0.05625 | K11: =ROUND(('EBs NPVs'!E18-'EBs NPVs'!D18)/30,0) -> 6 | L11: 44587 | M11: bullet | N11: 3250000 | O11: 0 | P11: 100
A12: USD 2023 | B12: USD 2023 | C12: U.S. dollar-denominated 4.625 per cent. International Bonds due 2023 (the “USD 2023 Bonds”) | D12: USD Bonds due 2021-2023 | E12: 2016 | F12: 43111 | G12: US040114HP86 | J12: 0.04625 | K12: =ROUND(('EBs NPVs'!E19-'EBs NPVs'!D19)/30,0) -> 6 | L12: 44937 | M12: bullet | N12: 1750000 | O12: 0 | P12: 100
A13: USD 2026 | B13: USD 2026 | C13: U.S. dollar-denominated 7.500 per cent. International Bonds due 2026 (the “USD 2026 Bonds”) | D13: USD Bonds due 2026-2036 | E13: 2016 | F13: 42482 | G13: US040114GX20 | H13: USP04808AC88 | I13: US040114GS35 | J13: 0.075 | K13: =ROUND(('EBs NPVs'!E20-'EBs NPVs'!D20)/30,0) -> 6 | L13: 46134 | M13: bullet | N13: 6454850 | O13: 45150 | P13: 100
A14: USD 2027 | B14: USD 2027 | C14: U.S. dollar-denominated 6.875 per cent. International Bonds due 2027 (the “USD 2027 Bonds”) | D14: USD Bonds due 2026-2036 | E14: 2016 | F14: 42761 | G14: US040114HL72 | H14: USP04808AM60 | J14: 0.06875 | K14: =ROUND(('EBs NPVs'!E21-'EBs NPVs'!D21)/30,0) -> 6 | L14: 46413 | M14: bullet | N14: 3750000 | O14: 0 | P14: 100
A15: USD 5.875% 2028 | B15: USD 5.875% 2028 | C15: U.S. dollar-denominated 5.875 per cent. International Bonds due 2028 (the “USD 5.875% 2028 Bonds”) | D15: USD Bonds due 2026-2036 | E15: 2016 | F15: 43111 | G15: US040114HQ69 | J15: 0.05875 | K15: =ROUND(('EBs NPVs'!E22-'EBs NPVs'!D22)/30,0) -> 6 | L15: 46763 | M15: bullet | N15: 4250000 | O15: 0 | P15: 100
A16: USD 6.625% 2028 | B16: USD 6.625% 2028 | C16: U.S. dollar-denominated 6.625 per cent. International Bonds due 2028 (the “USD 6.625% 2028 Bonds”) | D16: USD Bonds due 2026-2036 | E16: 2016 | F16: 42557 | G16: US040114HF05 | H16: USP04808AJ32 | J16: 0.06625 | K16: =ROUND(('EBs NPVs'!E23-'EBs NPVs'!D23)/30,0) -> 6 | L16: 46940 | M16: bullet | N16: 965000 | O16: 35000 | P16: 100
A17: USD 2036 | B17: USD 2036 | C17: U.S. dollar-denominated 7.125 per cent. International Bonds due 2036 (the “USD 2036 Bonds”) | D17: USD Bonds due 2026-2036 | E17: 2016 | F17: 42557 | G17: US040114HG87 | H17: USP04808AK05 | I17: US040114HE30 | J17: 0.07125 | K17: =ROUND(('EBs NPVs'!E24-'EBs NPVs'!D24)/30,0) -> 6 | L17: 49862 | M17: bullet | N17: 1727000 | O17: 23000 | P17: 100
A18: USD 2046 | B18: USD 2046 | C18: U.S. dollar-denominated 7.625 per cent. International Bonds due 2046 (the “USD 2046 Bonds”) | D18: USD Bonds due 2046-2117 | E18: 2016 | F18: 42482 | G18: US040114GY03 | H18: USP04808AE45 | I18: US040114GU80 | J18: 0.07625 | K18: =ROUND(('EBs NPVs'!E25-'EBs NPVs'!D25)/30,0) -> 6 | L18: 53439 | M18: bullet | N18: 2617685 | O18: 132315 | P18: 100
A19: USD 2048 | B19: USD 2048 | C19: U.S. dollar-denominated 6.875 per cent. International Bonds due 2048 (the “USD 2048 Bonds”) | D19: USD Bonds due 2046-2117 | E19: 2016 | F19: 43111 | G19: US040114HR43 | J19: 0.06875 | K19: =ROUND(('EBs NPVs'!E26-'EBs NPVs'!D26)/30,0) -> 6 | L19: 54068 | M19: bullet | N19: 3000000 | O19: 0 | P19: 100
A20: USD 2117 | B20: USD 2117 | C20: U.S. dollar-denominated 7.125 per cent. International Bonds due 2117 (the “USD 2117 Bonds”) | D20: USD Bonds due 2046-2117 | E20: 2016 | F20: 42914 | G20: USP04808AN44 | H20: US040114HM55 | I20: US040114HN39 | J20: 0.07125 | K20: =ROUND(('EBs NPVs'!E27-'EBs NPVs'!D27)/30,0) -> 6 | L20: 79438 | M20: bullet | N20: 2689176 | O20: 60824 | P20: 100
A21: Euro 2022 | B21: Euro 2022 | C21: Euro-denominated 3.875 per cent. International Bonds due 2022 (the “Euro 2022 Bonds”) | D21: Euro Bonds due 2022-2023 | E21: 2016 | F21: 42655 | G21: XS1503160225 | J21: 0.03875 | K21: =ROUND(('EBs NPVs'!E28-'EBs NPVs'!D28)/30,0) -> 12 | L21: 44576 | M21: bullet | N21: 1250000 | O21: 0 | P21: 100
A22: Euro 2023 | B22: Euro 2023 | C22: Euro-denominated 3.375 per cent. International Bonds due 2023 (the “Euro 2023 Bonds”) | D22: Euro Bonds due 2022-2023 | E22: 2016 | F22: 43048 | G22: XS1715303340 | J22: 0.03375 | K22: =ROUND(('EBs NPVs'!E29-'EBs NPVs'!D29)/30,0) -> 12 | L22: 44941 | M22: bullet | N22: 1000000 | O22: 0 | P22: 100
A23: Euro 2027 | B23: Euro 2027 | C23: Euro-denominated 5.000 per cent. International Bonds due 2027 (the “Euro 2027 Bonds”) | D23: Euro Bonds due 2027-2028 | E23: 2016 | F23: 42655 | G23: XS1503160498 | J23: 0.05 | K23: =ROUND(('EBs NPVs'!E30-'EBs NPVs'!D30)/30,0) -> 12 | L23: 46402 | M23: bullet | N23: 1250000 | O23: 0 | P23: 100
A24: Euro 2028 | B24: Euro 2028 | C24: Euro-denominated 5.250 per cent. International Bonds due 2028 (the “Euro 2028 Bonds”) | D24: Euro Bonds due 2027-2028 | E24: 2016 | F24: 43048 | G24: XS1715303779 | J24: 0.0525 | K24: =ROUND(('EBs NPVs'!E31-'EBs NPVs'!D31)/30,0) -> 12 | L24: 46767 | M24: bullet | N24: 1000000 | O24: 0 | P24: 100
A25: Euro 2047 | B25: Euro 2047 | C25: Euro-denominated 6.250 per cent. International Bonds due 2047 (the “Euro 2047 Bonds”) | D25: Euro Bonds due 2047 | E25: 2016 | F25: 43048 | G25: XS1715535123 | J25: 0.0625 | K25: =ROUND(('EBs NPVs'!E32-'EBs NPVs'!D32)/30,0) -> 12 | L25: 54005 | M25: bullet | N25: 750000 | O25: 0 | P25: 100
A26: CHF 2020 | B26: CHF 2020 | C26: Swiss Franc-denominated 3.375 per cent. International Bonds due 2020 (the “CHF 2020 Bonds”) | D26: CHF 2020 Bonds | E26: 2016 | F26: 42837 | G26: CH0361824458 | J26: 0.03375 | K26: =ROUND(('EBs NPVs'!E33-'EBs NPVs'!D33)/30,0) -> 12 | L26: 44116 | M26: bullet | N26: 400000 | O26: 0 | P26: 100

Sheet Kirchner EBs Cashflows
A1: USD Discounts | AQ1: Here you start repaying principal | BY1: Here you start repaying principal
A2: Dates | B2: 37986 | C2: =EDATE(B2,6) -> 38168 | D2: =EDATE(B2,12) -> 38352 | E2: =EDATE(C2,12) -> 38533 | F2: =EDATE(D2,12) -> 38717 | G2: =EDATE(E2,12) -> 38898 | H2: =EDATE(F2,12) -> 39082 | I2: =EDATE(G2,12) -> 39263 | J2: =EDATE(H2,12) -> 39447 | K2: =EDATE(I2,12) -> 39629 | ... BJ2: =EDATE(BH2,12) -> 48944
A3: Cash rate (t-1 to t) | B3: =3.97 -> 3.97 | C3: =3.97 -> 3.97 | D3: =3.97 -> 3.97 | E3: =3.97 -> 3.97 | F3: =3.97 -> 3.97 | G3: =3.97 -> 3.97 | H3: =3.97 -> 3.97 | I3: =3.97 -> 3.97 | ... L3: =3.97 -> 3.97 | M3: =5.77 -> 5.77 | N3: =5.77 -> 5.77 | O3: =5.77 -> 5.77 | P3: =5.77 -> 5.77 | Q3: =5.77 -> 5.77 | R3: =5.77 -> 5.77 | S3: =5.77 -> 5.77 | T3: =5.77 -> 5.77 | ... V3: =5.77 -> 5.77 | W3: 8.28 | X3: 8.28 | Y3: 8.28 | Z3: 8.28 | AA3: 8.28 | AB3: 8.28 | AC3: 8.28 | AD3: 8.28 | AE3: 8.28 | AF3: 8.28 | AG3: 8.28 | AH3: 8.28 | AI3: 8.28 | AJ3: 8.28 | AK3: 8.28 | AL3: 8.28 | AM3: 8.28 | AN3: 8.28 | AO3: 8.28 | AP3: 8.28 | AQ3: 8.28 | AR3: 8.28 | AS3: 8.28 | AT3: 8.28 | AU3: 8.28 | AV3: 8.28 | AW3: 8.28 | AX3: 8.28 | AY3: 8.28 | AZ3: 8.28 | BA3: 8.28 | BB3: 8.28 | BC3: 8.28 | BD3: 8.28 | BE3: 8.28 | BF3: 8.28 | BG3: 8.28 | BH3: 8.28 | BI3: 8.28 | BJ3: 8.28
A4: Cap.ed rate (t-1 to t) | B4: =4.31 -> 4.31 | C4: =4.31 -> 4.31 | D4: =4.31 -> 4.31 | E4: =4.31 -> 4.31 | F4: =4.31 -> 4.31 | G4: =4.31 -> 4.31 | H4: =4.31 -> 4.31 | I4: =4.31 -> 4.31 | ... L4: =4.31 -> 4.31 | M4: =2.51 -> 2.51 | N4: =2.51 -> 2.51 | O4: =2.51 -> 2.51 | P4: =2.51 -> 2.51 | Q4: =2.51 -> 2.51 | R4: =2.51 -> 2.51 | S4: =2.51 -> 2.51 | T4: =2.51 -> 2.51 | ... V4: =2.51 -> 2.51 | W4: 0 | X4: 0 | Y4: 0 | Z4: 0 | AA4: 0 | AB4: 0 | AC4: 0 | AD4: 0 | AE4: 0 | AF4: 0 | AG4: 0 | AH4: 0 | AI4: 0 | AJ4: 0 | AK4: 0 | AL4: 0 | AM4: 0 | AN4: 0 | AO4: 0 | AP4: 0 | AQ4: 0 | AR4: 0 | AS4: 0 | AT4: 0 | AU4: 0 | AV4: 0 | AW4: 0 | AX4: 0 | AY4: 0 | AZ4: 0 | BA4: 0 | BB4: 0 | BC4: 0 | BD4: 0 | BE4: 0 | BF4: 0 | BG4: 0 | BH4: 0 | BI4: 0 | BJ4: 0
A5: PA (on which to compute stuff) | B5: 100 | C5: =B5+B7-B8 -> 100 | D5: =C5+C7-C8 -> 102.155 | E5: =D5+D7-D8 -> 104.35644 | F5: =E5+E7-E8 -> 106.60532 | G5: =F5+F7-F8 -> 108.90267 | H5: =G5+G7-G8 -> 111.24952 | I5: =H5+H7-H8 -> 113.64695 | J5: =I5+I7-I8 -> 116.09604 | ... BJ5: =BI5+BI7-BI8 -> 7.0102106
A6: S/A Coupon payment | B6: 0 | C6: =C3/2*C5/100 -> 1.985 | D6: =D3/2*D5/100 -> 2.0277768 | E6: =E3/2*E5/100 -> 2.0714753 | F6: =F3/2*F5/100 -> 2.1161156 | G6: =G3/2*G5/100 -> 2.1617179 | H6: =H3/2*H5/100 -> 2.2083029 | I6: =I3/2*I5/100 -> 2.2558919 | J6: =J3/2*J5/100 -> 2.3045063 | ... BJ6: =BJ3/2*BJ5/100 -> 0.29022272
A7: Cap.ed amount | B7: 0 | C7: =C$5*C4/2/100 -> 2.155 | D7: =D$5*D4/2/100 -> 2.2014402 | E7: =E$5*E4/2/100 -> 2.2488813 | F7: =F$5*F4/2/100 -> 2.2973447 | G7: =G$5*G4/2/100 -> 2.3468525 | H7: =H$5*H4/2/100 -> 2.3974271 | I7: =I$5*I4/2/100 -> 2.4490917 | J7: =J$5*J4/2/100 -> 2.5018696 | ... BJ7: =BJ$5*BJ4/2/100 -> 0
A8: PA Amortization payment | B8: 0 | C8: 0 | D8: 0 | E8: 0 | F8: 0 | G8: 0 | H8: 0 | I8: 0 | J8: 0 | K8: 0 | L8: 0 | M8: 0 | N8: 0 | O8: 0 | P8: 0 | Q8: 0 | R8: 0 | S8: 0 | T8: 0 | U8: 0 | V8: 0 | W8: 0 | X8: 0 | Y8: 0 | Z8: 0 | AA8: 0 | AB8: 0 | AC8: 0 | AD8: 0 | AE8: 0 | AF8: 0 | AG8: 0 | AH8: 0 | AI8: 0 | AJ8: 0 | AK8: 0 | AL8: 0 | AM8: 0 | AN8: 0 | AO8: 0 | AP8: 0 | AQ8: =AQ5/20 -> 7.0102106 | AR8: =AQ8 -> 7.0102106 | AS8: =AR8 -> 7.0102106 | AT8: =AS8 -> 7.0102106 | AU8: =AT8 -> 7.0102106 | AV8: =AU8 -> 7.0102106 | AW8: =AV8 -> 7.0102106 | AX8: =AW8 -> 7.0102106 | AY8: =AX8 -> 7.0102106 | ... BJ8: =BI8 -> 7.0102106
A9: Total Cash Flow | B9: =B8+B6 -> 0 | C9: =C8+C6 -> 1.985 | D9: =D8+D6 -> 2.0277768 | E9: =E8+E6 -> 2.0714753 | F9: =F8+F6 -> 2.1161156 | G9: =G8+G6 -> 2.1617179 | H9: =H8+H6 -> 2.2083029 | I9: =I8+I6 -> 2.2558919 | ... BJ9: =BJ8+BJ6 -> 7.3004333
A11: USD Pars | C11: First cpn /2 because of 3 months period | M11: x | BU11: Last cpn /2 because of 3 months period
A12: Dates | B12: 37986 | C12: =EDATE(B12,3) -> 38077 | D12: =EDATE(C12,6) -> 38260 | E12: =EDATE(C12,12) -> 38442 | F12: =EDATE(D12,12) -> 38625 | G12: =EDATE(E12,12) -> 38807 | H12: =EDATE(F12,12) -> 38990 | I12: =EDATE(G12,12) -> 39172 | J12: =EDATE(H12,12) -> 39355 | K12: =EDATE(I12,12) -> 39538 | L12: =EDATE(J12,12) -> 39721 | ... BT12: =EDATE(BR12,12) -> 50678 | BU12: 50770
A13: ANNUAL Coupon rate (t-1 to t) | B13: 1.33 | C13: 1.33 | D13: 1.33 | E13: 1.33 | F13: 1.33 | G13: 1.33 | H13: 1.33 | I13: 1.33 | J13: 1.33 | K13: 1.33 | L13: 1.33 | M13: 1.33 | N13: 2.5 | O13: 2.5 | P13: 2.5 | Q13: 2.5 | R13: 2.5 | S13: 2.5 | T13: 2.5 | U13: 2.5 | V13: 2.5 | W13: 2.5 | X13: 2.5 | Y13: 2.5 | Z13: 2.5 | AA13: 2.5 | AB13: 2.5 | AC13: 2.5 | AD13: 2.5 | AE13: 2.5 | AF13: 2.5 | AG13: 2.5 | AH13: 3.75 | AI13: 3.75 | AJ13: 3.75 | AK13: 3.75 | AL13: 3.75 | AM13: 3.75 | AN13: 3.75 | AO13: 3.75 | AP13: 3.75 | AQ13: 3.75 | AR13: 3.75 | AS13: 3.75 | AT13: 3.75 | AU13: 3.75 | AV13: 3.75 | AW13: 3.75 | AX13: 3.75 | AY13: 3.75 | AZ13: 3.75 | BA13: 3.75 | BB13: 5.25 | BC13: 5.25 | BD13: 5.25 | BE13: 5.25 | BF13: 5.25 | BG13: 5.25 | BH13: 5.25 | BI13: 5.25 | BJ13: 5.25 | BK13: 5.25 | BL13: 5.25 | BM13: 5.25 | BN13: 5.25 | BO13: 5.25 | BP13: 5.25 | BQ13: 5.25 | BR13: 5.25 | BS13: 5.25 | BT13: 5.25 | BU13: 5.25
A14: PA (on which to compute stuff) | B14: 100 | C14: =B14-B16 -> 100 | D14: =C14-C16 -> 100 | E14: =D14-D16 -> 100 | F14: =E14-E16 -> 100 | G14: =F14-F16 -> 100 | H14: =G14-G16 -> 100 | I14: =H14-H16 -> 100 | J14: =I14-I16 -> 100 | ... BU14: =BT14-BT16 -> 5
A15: S/A Coupon payment | B15: 0 | C15: =C14*C13/2/100/2 -> 0.3325 | D15: =D14*D13/2/100 -> 0.665 | E15: =E14*E13/2/100 -> 0.665 | F15: =F14*F13/2/100 -> 0.665 | G15: =G14*G13/2/100 -> 0.665 | H15: =H14*H13/2/100 -> 0.665 | I15: =I14*I13/2/100 -> 0.665 | J15: =J14*J13/2/100 -> 0.665 | K15: =K14*K13/2/100 -> 0.665 | ... BT15: =BT14*BT13/2/100 -> 0.2625 | BU15: =BU14*BU13/2/100/2 -> 0.065625
A16: PA Amortization payment | B16: 0 | C16: 0 | D16: 0 | E16: 0 | F16: 0 | G16: 0 | H16: 0 | I16: 0 | J16: 0 | K16: 0 | L16: 0 | M16: 0 | N16: 0 | O16: 0 | P16: 0 | Q16: 0 | R16: 0 | S16: 0 | T16: 0 | U16: 0 | V16: 0 | W16: 0 | X16: 0 | Y16: 0 | Z16: 0 | AA16: 0 | AB16: 0 | AC16: 0 | AD16: 0 | AE16: 0 | AF16: 0 | AG16: 0 | AH16: 0 | AI16: 0 | AJ16: 0 | AK16: 0 | AL16: 0 | AM16: 0 | AN16: 0 | AO16: 0 | AP16: 0 | AQ16: 0 | AR16: 0 | AS16: 0 | AT16: 0 | AU16: 0 | AV16: 0 | AW16: 0 | AX16: 0 | AY16: 0 | AZ16: 0 | BA16: 0 | BB16: =BA14/20 -> 5 | BC16: =BB16 -> 5 | BD16: =BC16 -> 5 | BE16: =BD16 -> 5 | BF16: =BE16 -> 5 | BG16: =BF16 -> 5 | BH16: =BG16 -> 5 | BI16: =BH16 -> 5 | BJ16: =BI16 -> 5 | ... BU16: =BT16 -> 5
A17: Total Cash Flow | B17: =B16+B15 -> 0 | C17: =C16+C15 -> 0.3325 | D17: =D16+D15 -> 0.665 | E17: =E16+E15 -> 0.665 | F17: =F16+F15 -> 0.665 | G17: =G16+G15 -> 0.665 | H17: =H16+H15 -> 0.665 | I17: =I16+I15 -> 0.665 | ... BU17: =BU16+BU15 -> 5.065625
A19: EUR Discounts | AQ19: Here you start repaying principal
A20: Dates | B20: 37986 | C20: =EDATE(B20,6) -> 38168 | D20: =EDATE(B20,12) -> 38352 | E20: =EDATE(C20,12) -> 38533 | F20: =EDATE(D20,12) -> 38717 | G20: =EDATE(E20,12) -> 38898 | H20: =EDATE(F20,12) -> 39082 | I20: =EDATE(G20,12) -> 39263 | J20: =EDATE(H20,12) -> 39447 | K20: =EDATE(I20,12) -> 39629 | ... BJ20: =EDATE(BH20,12) -> 48944
A21: Cash rate (t-1 to t) | B21: 3.75 | C21: 3.75 | D21: 3.75 | E21: 3.75 | F21: 3.75 | G21: 3.75 | H21: 3.75 | I21: 3.75 | J21: 3.75 | K21: 3.75 | L21: 3.75 | M21: 5.45 | N21: 5.45 | O21: 5.45 | P21: 5.45 | Q21: 5.45 | R21: 5.45 | S21: 5.45 | T21: 5.45 | U21: 5.45 | V21: 5.45 | W21: 7.82 | X21: 7.82 | Y21: 7.82 | Z21: 7.82 | AA21: 7.82 | AB21: 7.82 | AC21: 7.82 | AD21: 7.82 | AE21: 7.82 | AF21: 7.82 | AG21: 7.82 | AH21: 7.82 | AI21: 7.82 | AJ21: 7.82 | AK21: 7.82 | AL21: 7.82 | AM21: 7.82 | AN21: 7.82 | AO21: 7.82 | AP21: 7.82 | AQ21: 7.82 | AR21: 7.82 | AS21: 7.82 | AT21: 7.82 | AU21: 7.82 | AV21: 7.82 | AW21: 7.82 | AX21: 7.82 | AY21: 7.82 | AZ21: 7.82 | BA21: 7.82 | BB21: 7.82 | BC21: 7.82 | BD21: 7.82 | BE21: 7.82 | BF21: 7.82 | BG21: 7.82 | BH21: 7.82 | BI21: 7.82 | BJ21: 7.82
A22: Cap.ed rate (t-1 to t) | B22: 4.07 | C22: 4.07 | D22: 4.07 | E22: 4.07 | F22: 4.07 | G22: 4.07 | H22: 4.07 | I22: 4.07 | J22: 4.07 | K22: 4.07 | L22: 4.07 | M22: 2.37 | N22: 2.37 | O22: 2.37 | P22: 2.37 | Q22: 2.37 | R22: 2.37 | S22: 2.37 | T22: 2.37 | U22: 2.37 | V22: 2.37 | W22: 0 | X22: 0 | Y22: 0 | Z22: 0 | AA22: 0 | AB22: 0 | AC22: 0 | AD22: 0 | AE22: 0 | AF22: 0 | AG22: 0 | AH22: 0 | AI22: 0 | AJ22: 0 | AK22: 0 | AL22: 0 | AM22: 0 | AN22: 0 | AO22: 0 | AP22: 0 | AQ22: 0 | AR22: 0 | AS22: 0 | AT22: 0 | AU22: 0 | AV22: 0 | AW22: 0 | AX22: 0 | AY22: 0 | AZ22: 0 | BA22: 0 | BB22: 0 | BC22: 0 | BD22: 0 | BE22: 0 | BF22: 0 | BG22: 0 | BH22: 0 | BI22: 0 | BJ22: 0
A23: PA (on which to compute stuff) | B23: 100 | C23: =B23+B25-B26 -> 100 | D23: =C23+C25-C26 -> 102.035 | E23: =D23+D25-D26 -> 104.11385 | F23: =E23+E25-E26 -> 106.23751 | G23: =F23+F25-F26 -> 108.40693 | H23: =G23+G25-G26 -> 110.6231 | I23: =H23+H25-H26 -> 112.88702 | J23: =I23+I25-I26 -> 115.19974 | ... BJ23: =BI23+BI25-BI26 -> 6.8981971
A24: S/A Coupon payment | B24: 0 | C24: =C21/2*C23/100 -> 1.875 | D24: =D21/2*D23/100 -> 1.9131562 | E24: =E21/2*E23/100 -> 1.9521348 | F24: =F21/2*F23/100 -> 1.9919533 | G24: =G21/2*G23/100 -> 2.0326299 | H24: =H21/2*H23/100 -> 2.074183 | I24: =I21/2*I23/100 -> 2.1166317 | J24: =J21/2*J23/100 -> 2.1599951 | ... BJ24: =BJ21/2*BJ23/100 -> 0.26971951
A25: Cap.ed amount | B25: 0 | C25: =C$5*C22/2/100 -> 2.035 | D25: =D$5*D22/2/100 -> 2.0788543 | E25: =E$5*E22/2/100 -> 2.1236536 | F25: =F$5*F22/2/100 -> 2.1694183 | G25: =G$5*G22/2/100 -> 2.2161693 | H25: =H$5*H22/2/100 -> 2.2639277 | I25: =I$5*I22/2/100 -> 2.3127153 | J25: =J$5*J22/2/100 -> 2.3625544 | ... BJ25: =BJ$5*BJ22/2/100 -> 0
A26: PA Amortization payment | B26: 0 | C26: 0 | D26: 0 | E26: 0 | F26: 0 | G26: 0 | H26: 0 | I26: 0 | J26: 0 | K26: 0 | L26: 0 | M26: 0 | N26: 0 | O26: 0 | P26: 0 | Q26: 0 | R26: 0 | S26: 0 | T26: 0 | U26: 0 | V26: 0 | W26: 0 | X26: 0 | Y26: 0 | Z26: 0 | AA26: 0 | AB26: 0 | AC26: 0 | AD26: 0 | AE26: 0 | AF26: 0 | AG26: 0 | AH26: 0 | AI26: 0 | AJ26: 0 | AK26: 0 | AL26: 0 | AM26: 0 | AN26: 0 | AO26: 0 | AP26: 0 | AQ26: =AQ23/20 -> 6.8981971 | AR26: =AQ26 -> 6.8981971 | AS26: =AR26 -> 6.8981971 | AT26: =AS26 -> 6.8981971 | AU26: =AT26 -> 6.8981971 | AV26: =AU26 -> 6.8981971 | AW26: =AV26 -> 6.8981971 | AX26: =AW26 -> 6.8981971 | AY26: =AX26 -> 6.8981971 | ... BJ26: =BI26 -> 6.8981971
A27: Total Cash Flow | B27: =B26+B24 -> 0 | C27: =C26+C24 -> 1.875 | D27: =D26+D24 -> 1.9131562 | E27: =E26+E24 -> 1.9521348 | F27: =F26+F24 -> 1.9919533 | G27: =G26+G24 -> 2.0326299 | H27: =H26+H24 -> 2.074183 | I27: =I26+I24 -> 2.1166317 | ... BJ27: =BJ26+BJ24 -> 7.1679167
A29: EUR Pars | C29: First cpn /2 because of 3 months period | M29: x | BU29: Last cpn /2 because of 3 months period
A30: Dates | B30: 37986 | C30: =EDATE(B30,3) -> 38077 | D30: =EDATE(C30,6) -> 38260 | E30: =EDATE(C30,12) -> 38442 | F30: =EDATE(D30,12) -> 38625 | G30: =EDATE(E30,12) -> 38807 | H30: =EDATE(F30,12) -> 38990 | I30: =EDATE(G30,12) -> 39172 | J30: =EDATE(H30,12) -> 39355 | K30: =EDATE(I30,12) -> 39538 | L30: =EDATE(J30,12) -> 39721 | ... BT30: =EDATE(BR30,12) -> 50678 | BU30: 50770
A31: ANNUAL Coupon rate (t-1 to t) | B31: 1.2 | C31: 1.2 | D31: 1.2 | E31: 1.2 | F31: 1.2 | G31: 1.2 | H31: 1.2 | I31: 1.2 | J31: 1.2 | K31: 1.2 | L31: 1.2 | M31: 1.2 | N31: 2.26 | O31: 2.26 | P31: 2.26 | Q31: 2.26 | R31: 2.26 | S31: 2.26 | T31: 2.26 | U31: 2.26 | V31: 2.26 | W31: 2.26 | X31: 2.26 | Y31: 2.26 | Z31: 2.26 | AA31: 2.26 | AB31: 2.26 | AC31: 2.26 | AD31: 2.26 | AE31: 2.26 | AF31: 2.26 | AG31: 2.26 | AH31: 3.38 | AI31: 3.38 | AJ31: 3.38 | AK31: 3.38 | AL31: 3.38 | AM31: 3.38 | AN31: 3.38 | AO31: 3.38 | AP31: 3.38 | AQ31: 3.38 | AR31: 3.38 | AS31: 3.38 | AT31: 3.38 | AU31: 3.38 | AV31: 3.38 | AW31: 3.38 | AX31: 3.38 | AY31: 3.38 | AZ31: 3.38 | BA31: 3.38 | BB31: 4.74 | BC31: 4.74 | BD31: 4.74 | BE31: 4.74 | BF31: 4.74 | BG31: 4.74 | BH31: 4.74 | BI31: 4.74 | BJ31: 4.74 | BK31: 4.74 | BL31: 4.74 | BM31: 4.74 | BN31: 4.74 | BO31: 4.74 | BP31: 4.74 | BQ31: 4.74 | BR31: 4.74 | BS31: 4.74 | BT31: 4.74 | BU31: 4.74
A32: PA (on which to compute stuff) | B32: 100 | C32: =B32-B34 -> 100 | D32: =C32-C34 -> 100 | E32: =D32-D34 -> 100 | F32: =E32-E34 -> 100 | G32: =F32-F34 -> 100 | H32: =G32-G34 -> 100 | I32: =H32-H34 -> 100 | J32: =I32-I34 -> 100 | ... BU32: =BT32-BT34 -> 5
A33: S/A Coupon payment | B33: 0 | C33: =C32*C31/2/100/2 -> 0.3 | D33: =D32*D31/2/100 -> 0.6 | E33: =E32*E31/2/100 -> 0.6 | F33: =F32*F31/2/100 -> 0.6 | G33: =G32*G31/2/100 -> 0.6 | H33: =H32*H31/2/100 -> 0.6 | I33: =I32*I31/2/100 -> 0.6 | J33: =J32*J31/2/100 -> 0.6 | K33: =K32*K31/2/100 -> 0.6 | ... BT33: =BT32*BT31/2/100 -> 0.237 | BU33: =BU32*BU31/2/100/2 -> 0.05925
A34: PA Amortization payment | B34: 0 | C34: 0 | D34: 0 | E34: 0 | F34: 0 | G34: 0 | H34: 0 | I34: 0 | J34: 0 | K34: 0 | L34: 0 | M34: 0 | N34: 0 | O34: 0 | P34: 0 | Q34: 0 | R34: 0 | S34: 0 | T34: 0 | U34: 0 | V34: 0 | W34: 0 | X34: 0 | Y34: 0 | Z34: 0 | AA34: 0 | AB34: 0 | AC34: 0 | AD34: 0 | AE34: 0 | AF34: 0 | AG34: 0 | AH34: 0 | AI34: 0 | AJ34: 0 | AK34: 0 | AL34: 0 | AM34: 0 | AN34: 0 | AO34: 0 | AP34: 0 | AQ34: 0 | AR34: 0 | AS34: 0 | AT34: 0 | AU34: 0 | AV34: 0 | AW34: 0 | AX34: 0 | AY34: 0 | AZ34: 0 | BA34: 0 | BB34: =BA32/20 -> 5 | BC34: =BB34 -> 5 | BD34: =BC34 -> 5 | BE34: =BD34 -> 5 | BF34: =BE34 -> 5 | BG34: =BF34 -> 5 | BH34: =BG34 -> 5 | BI34: =BH34 -> 5 | BJ34: =BI34 -> 5 | ... BU34: =BT34 -> 5
A35: Total Cash Flow | B35: =B34+B33 -> 0 | C35: =C34+C33 -> 0.3 | D35: =D34+D33 -> 0.6 | E35: =E34+E33 -> 0.6 | F35: =F34+F33 -> 0.6 | G35: =G34+G33 -> 0.6 | H35: =H34+H33 -> 0.6 | I35: =I34+I33 -> 0.6 | ... BU35: =BU34+BU33 -> 5.05925

Sheet EBs NPVs
B1: Valuation date | C1: 44089 | GQ1: x
B2: Exit yields (Principal Amount-weighted averages)
B3: USD2005 | C3: ='NBs Prices'!G49 -> 11.341845
B4: EUR2005 | C4: ='NBs Prices'!G50 -> 13.393885
B5: USD2016 | C5: ='NBs Prices'!G51 -> 11.513868 | E5: Max date | F5: Min date
B6: EUR2016 | C6: ='NBs Prices'!G52 -> 14.151281 | E6: =MAX(E9:E33) -> 44038 | F6: =MIN(F9:F33) -> 44104
B8: ISIN | C8: Short Name | E8: Payment dates
B9: US040114GL81 | C9: USD 2033 Discount I | D9: =EDATE(E9,-ROUND((F9-E9)/30,0)) -> 43829 | E9: 44012 | F9: 44196 | G9: 44377 | H9: 44561 | I9: 44742 | J9: 44926 | K9: 45107 | L9: 45291 | M9: 45473 | N9: 45657 | O9: 45838 | P9: 46022 | Q9: 46203 | R9: 46387 | S9: 46568 | T9: 46752 | U9: 46934 | V9: 47118 | W9: 47299 | X9: 47483 | Y9: 47664 | Z9: 47848 | AA9: 48029 | AB9: 48213 | AC9: 48395 | AD9: 48579 | AE9: 48760 | AF9: 48944
B10: XS0501194756 | C10: USD 2033 Discount II and III | D10: =EDATE(E10,-ROUND((F10-E10)/30,0)) -> 43829 | E10: 44012 | F10: 44196 | G10: 44377 | H10: 44561 | I10: 44742 | J10: 44926 | K10: 45107 | L10: 45291 | M10: 45473 | N10: 45657 | O10: 45838 | P10: 46022 | Q10: 46203 | R10: 46387 | S10: 46568 | T10: 46752 | U10: 46934 | V10: 47118 | W10: 47299 | X10: 47483 | Y10: 47664 | Z10: 47848 | AA10: 48029 | AB10: 48213 | AC10: 48395 | AD10: 48579 | AE10: 48760 | AF10: 48944
B11: US040114GK09 | C11: USD Par 2038 I | D11: =EDATE(E11,-ROUND((F11-E11)/30,0)) -> 43738 | E11: 43921 | F11: 44104 | G11: 44286 | H11: 44469 | I11: 44651 | J11: 44834 | K11: 45016 | L11: 45199 | M11: 45382 | N11: 45565 | O11: 45747 | P11: 45930 | Q11: 46112 | R11: 46295 | S11: 46477 | T11: 46660 | U11: 46843 | V11: 47026 | W11: 47208 | X11: 47391 | Y11: 47573 | Z11: 47756 | AA11: 47938 | AB11: 48121 | AC11: 48304 | AD11: 48487 | AE11: 48669 | AF11: 48852 | AG11: 49034 | AH11: 49217 | AI11: 49399 | AJ11: 49582 | AK11: 49765 | AL11: 49948 | AM11: 50130 | AN11: 50313 | AO11: 50495 | AP11: 50678 | AQ11: 50770
B12: XS0501195647 | C12: USD Par 2038 II and III | D12: =EDATE(E12,-ROUND((F12-E12)/30,0)) -> 43738 | E12: 43921 | F12: 44104 | G12: 44286 | H12: 44469 | I12: 44651 | J12: 44834 | K12: 45016 | L12: 45199 | M12: 45382 | N12: 45565 | O12: 45747 | P12: 45930 | Q12: 46112 | R12: 46295 | S12: 46477 | T12: 46660 | U12: 46843 | V12: 47026 | W12: 47208 | X12: 47391 | Y12: 47573 | Z12: 47756 | AA12: 47938 | AB12: 48121 | AC12: 48304 | AD12: 48487 | AE12: 48669 | AF12: 48852 | AG12: 49034 | AH12: 49217 | AI12: 49399 | AJ12: 49582 | AK12: 49765 | AL12: 49948 | AM12: 50130 | AN12: 50313 | AO12: 50495 | AP12: 50678 | AQ12: 50770
B13: XS0205545840 | C13: Euro 2033 Discount I | D13: =EDATE(E13,-ROUND((F13-E13)/30,0)) -> 43829 | E13: 44012 | F13: 44196 | G13: 44377 | H13: 44561 | I13: 44742 | J13: 44926 | K13: 45107 | L13: 45291 | M13: 45473 | N13: 45657 | O13: 45838 | P13: 46022 | Q13: 46203 | R13: 46387 | S13: 46568 | T13: 46752 | U13: 46934 | V13: 47118 | W13: 47299 | X13: 47483 | Y13: 47664 | Z13: 47848 | AA13: 48029 | AB13: 48213 | AC13: 48395 | AD13: 48579 | AE13: 48760 | AF13: 48944
B14: XS0501195134 | C14: Euro 2033 Discount II and III | D14: =EDATE(E14,-ROUND((F14-E14)/30,0)) -> 43829 | E14: 44012 | F14: 44196 | G14: 44377 | H14: 44561 | I14: 44742 | J14: 44926 | K14: 45107 | L14: 45291 | M14: 45473 | N14: 45657 | O14: 45838 | P14: 46022 | Q14: 46203 | R14: 46387 | S14: 46568 | T14: 46752 | U14: 46934 | V14: 47118 | W14: 47299 | X14: 47483 | Y14: 47664 | Z14: 47848 | AA14: 48029 | AB14: 48213 | AC14: 48395 | AD14: 48579 | AE14: 48760 | AF14: 48944
B15: XS0205537581 | C15: Euro Par 2038 I | D15: =EDATE(E15,-ROUND((F15-E15)/30,0)) -> 43738 | E15: 43921 | F15: 44104 | G15: 44286 | H15: 44469 | I15: 44651 | J15: 44834 | K15: 45016 | L15: 45199 | M15: 45382 | N15: 45565 | O15: 45747 | P15: 45930 | Q15: 46112 | R15: 46295 | S15: 46477 | T15: 46660 | U15: 46843 | V15: 47026 | W15: 47208 | X15: 47391 | Y15: 47573 | Z15: 47756 | AA15: 47938 | AB15: 48121 | AC15: 48304 | AD15: 48487 | AE15: 48669 | AF15: 48852 | AG15: 49034 | AH15: 49217 | AI15: 49399 | AJ15: 49582 | AK15: 49765 | AL15: 49948 | AM15: 50130 | AN15: 50313 | AO15: 50495 | AP15: 50678 | AQ15: 50770
B16: XS0501195993 | C16: Euro Par 2038 II and III | D16: =EDATE(E16,-ROUND((F16-E16)/30,0)) -> 43738 | E16: 43921 | F16: 44104 | G16: 44286 | H16: 44469 | I16: 44651 | J16: 44834 | K16: 45016 | L16: 45199 | M16: 45382 | N16: 45565 | O16: 45747 | P16: 45930 | Q16: 46112 | R16: 46295 | S16: 46477 | T16: 46660 | U16: 46843 | V16: 47026 | W16: 47208 | X16: 47391 | Y16: 47573 | Z16: 47756 | AA16: 47938 | AB16: 48121 | AC16: 48304 | AD16: 48487 | AE16: 48669 | AF16: 48852 | AG16: 49034 | AH16: 49217 | AI16: 49399 | AJ16: 49582 | AK16: 49765 | AL16: 49948 | AM16: 50130 | AN16: 50313 | AO16: 50495 | AP16: 50678 | AQ16: 50770
B17: US040114GW47 | C17: USD 2021 | D17: =EDATE(E17,-ROUND((F17-E17)/30,0)) -> 43760 | E17: 43943 | F17: 44126 | G17: 44308
B18: US040114HK99 | C18: USD 2022 | D18: =EDATE(E18,-ROUND((F18-E18)/30,0)) -> 43856 | E18: 44038 | F18: 44222 | G18: 44403 | H18: 44587
B19: US040114HP86 | C19: USD 2023 | D19: =EDATE(E19,-ROUND((F19-E19)/30,0)) -> 43841 | E19: 44023 | F19: 44207 | G19: 44388 | H19: 44572 | I19: 44753 | J19: 44937
B20: US040114GX20 | C20: USD 2026 | D20: =EDATE(E20,-ROUND((F20-E20)/30,0)) -> 43760 | E20: 43943 | F20: 44126 | G20: 44308 | H20: 44491 | I20: 44673 | J20: 44856 | K20: 45038 | L20: 45221 | M20: 45404 | N20: 45587 | O20: 45769 | P20: 45952 | Q20: 46134
B21: US040114HL72 | C21: USD 2027 | D21: =EDATE(E21,-ROUND((F21-E21)/30,0)) -> 43856 | E21: 44038 | F21: 44222 | G21: 44403 | H21: 44587 | I21: 44768 | J21: 44952 | K21: 45133 | L21: 45317 | M21: 45499 | N21: 45683 | O21: 45864 | P21: 46048 | Q21: 46229 | R21: 46413
B22: US040114HQ69 | C22: USD 5.875% 2028 | D22: =EDATE(E22,-ROUND((F22-E22)/30,0)) -> 43841 | E22: 44023 | F22: 44207 | G22: 44388 | H22: 44572 | I22: 44753 | J22: 44937 | K22: 45118 | L22: 45302 | M22: 45484 | N22: 45668 | O22: 45849 | P22: 46033 | Q22: 46214 | R22: 46398 | S22: 46579 | T22: 46763
B23: US040114HF05 | C23: USD 6.625% 2028 | D23: =EDATE(E23,-ROUND((F23-E23)/30,0)) -> 43836 | E23: 44018 | F23: =EDATE(E23,6) -> 44202 | G23: =EDATE(F23,6) -> 44383 | H23: =EDATE(G23,6) -> 44567 | I23: =EDATE(H23,6) -> 44748 | J23: =EDATE(I23,6) -> 44932 | K23: =EDATE(J23,6) -> 45113 | L23: =EDATE(K23,6) -> 45297 | M23: =EDATE(L23,6) -> 45479 | ... U23: =EDATE(T23,6) -> 46940
B24: US040114HG87 | C24: USD 2036 | D24: =EDATE(E24,-ROUND((F24-E24)/30,0)) -> 43836 | E24: 44018 | F24: 44202 | G24: 44383 | H24: 44567 | I24: 44748 | J24: 44932 | K24: 45113 | L24: 45297 | M24: 45479 | N24: 45663 | O24: 45844 | P24: 46028 | Q24: 46209 | R24: 46393 | S24: 46574 | T24: 46758 | U24: 46940 | V24: 47124 | W24: 47305 | X24: 47489 | Y24: 47670 | Z24: 47854 | AA24: 48035 | AB24: 48219 | AC24: 48401 | AD24: 48585 | AE24: 48766 | AF24: 48950 | AG24: 49131 | AH24: 49315 | AI24: 49496 | AJ24: 49680 | AK24: 49862
B25: US040114GY03 | C25: USD 2046 | D25: =EDATE(E25,-ROUND((F25-E25)/30,0)) -> 43760 | E25: 43943 | F25: 44126 | G25: 44308 | H25: 44491 | I25: 44673 | J25: 44856 | K25: 45038 | L25: 45221 | M25: 45404 | N25: 45587 | O25: 45769 | P25: 45952 | Q25: 46134 | R25: 46317 | S25: 46499 | T25: 46682 | U25: 46865 | V25: 47048 | W25: 47230 | X25: 47413 | Y25: 47595 | Z25: 47778 | AA25: 47960 | AB25: 48143 | AC25: 48326 | AD25: 48509 | AE25: 48691 | AF25: 48874 | AG25: 49056 | AH25: 49239 | AI25: 49421 | AJ25: 49604 | AK25: 49787 | AL25: 49970 | AM25: 50152 | AN25: 50335 | AO25: 50517 | AP25: 50700 | AQ25: 50882 | AR25: 51065 | AS25: 51248 | AT25: 51431 | AU25: 51613 | AV25: 51796 | AW25: 51978 | AX25: 52161 | AY25: 52343 | AZ25: 52526 | BA25: 52709 | BB25: 52892 | BC25: 53074 | BD25: 53257 | BE25: 53439
B26: US040114HR43 | C26: USD 2048 | D26: =EDATE(E26,-ROUND((F26-E26)/30,0)) -> 43841 | E26: 44023 | F26: 44207 | G26: 44388 | H26: 44572 | I26: 44753 | J26: 44937 | K26: 45118 | L26: 45302 | M26: 45484 | N26: 45668 | O26: 45849 | P26: 46033 | Q26: 46214 | R26: 46398 | S26: 46579 | T26: 46763 | U26: 46945 | V26: 47129 | W26: 47310 | X26: 47494 | Y26: 47675 | Z26: 47859 | AA26: 48040 | AB26: 48224 | AC26: 48406 | AD26: 48590 | AE26: 48771 | AF26: 48955 | AG26: 49136 | AH26: 49320 | AI26: 49501 | AJ26: 49685 | AK26: 49867 | AL26: 50051 | AM26: 50232 | AN26: 50416 | AO26: 50597 | AP26: 50781 | AQ26: 50962 | AR26: 51146 | AS26: 51328 | AT26: 51512 | AU26: 51693 | AV26: 51877 | AW26: 52058 | AX26: 52242 | AY26: 52423 | AZ26: 52607 | BA26: 52789 | BB26: 52973 | BC26: 53154 | BD26: 53338 | BE26: 53519 | BF26: 53703 | BG26: 53884 | BH26: 54068
B27: USP04808AN44 | C27: USD 2117 | D27: =EDATE(E27,-ROUND((F27-E27)/30,0)) -> 43827 | E27: 44010 | F27: =EDATE(E27,6) -> 44193 | G27: =EDATE(F27,6) -> 44375 | H27: =EDATE(G27,6) -> 44558 | I27: =EDATE(H27,6) -> 44740 | J27: =EDATE(I27,6) -> 44923 | K27: =EDATE(J27,6) -> 45105 | L27: =EDATE(K27,6) -> 45288 | M27: =EDATE(L27,6) -> 45471 | ... GQ27: =EDATE(GP27,6) -> 79438
B28: XS1503160225 | C28: Euro 2022 | D28: =EDATE(E28,-ROUND((F28-E28)/30,0)) -> 43480 | E28: 43845 | F28: =EDATE(E28,12) -> 44211 | G28: =EDATE(F28,12) -> 44576
B29: XS1715303340 | C29: Euro 2023 | D29: =EDATE(E29,-ROUND((F29-E29)/30,0)) -> 43480 | E29: 43845 | F29: =EDATE(E29,12) -> 44211 | G29: =EDATE(F29,12) -> 44576 | H29: =EDATE(G29,12) -> 44941
B30: XS1503160498 | C30: Euro 2027 | D30: =EDATE(E30,-ROUND((F30-E30)/30,0)) -> 43480 | E30: 43845 | F30: =EDATE(E30,12) -> 44211 | G30: =EDATE(F30,12) -> 44576 | H30: =EDATE(G30,12) -> 44941 | I30: =EDATE(H30,12) -> 45306 | J30: =EDATE(I30,12) -> 45672 | K30: =EDATE(J30,12) -> 46037 | L30: =EDATE(K30,12) -> 46402
B31: XS1715303779 | C31: Euro 2028 | D31: =EDATE(E31,-ROUND((F31-E31)/30,0)) -> 43480 | E31: 43845 | F31: =EDATE(E31,12) -> 44211 | G31: =EDATE(F31,12) -> 44576 | H31: =EDATE(G31,12) -> 44941 | I31: =EDATE(H31,12) -> 45306 | J31: =EDATE(I31,12) -> 45672 | K31: =EDATE(J31,12) -> 46037 | L31: =EDATE(K31,12) -> 46402 | M31: =EDATE(L31,12) -> 46767
B32: XS1715535123 | C32: Euro 2047 | D32: =EDATE(E32,-ROUND((F32-E32)/30,0)) -> 43413 | E32: 43778 | F32: =EDATE(E32,12) -> 44144 | G32: =EDATE(F32,12) -> 44509 | H32: =EDATE(G32,12) -> 44874 | I32: =EDATE(H32,12) -> 45239 | J32: =EDATE(I32,12) -> 45605 | K32: =EDATE(J32,12) -> 45970 | L32: =EDATE(K32,12) -> 46335 | M32: =EDATE(L32,12) -> 46700 | ... AG32: =EDATE(AF32,12) -> 54005
B33: CH0361824458 | C33: CHF 2020 | D33: =EDATE(E33,-ROUND((F33-E33)/30,0)) -> 43385 | E33: 43750 | F33: =EDATE(E33,12) -> 44116
E35: Note on below: First column is in the past so assuming no CF there. Second column is in less than 1 payment period, so we compute the accrued coupon.
B36: ISIN | C36: Short Name | E36: Cash Flows (Coupons + Redemptions) for 100 USD Notional.
B37: US040114GL81 | C37: =C9 -> USD 2033 Discount I | F37: ='Kirchner EBs Cashflows'!AJ9 -> 5.8044544 | G37: ='Kirchner EBs Cashflows'!AK9 -> 5.8044544 | H37: ='Kirchner EBs Cashflows'!AL9 -> 5.8044544 | I37: ='Kirchner EBs Cashflows'!AM9 -> 5.8044544 | J37: ='Kirchner EBs Cashflows'!AN9 -> 5.8044544 | K37: ='Kirchner EBs Cashflows'!AO9 -> 5.8044544 | L37: ='Kirchner EBs Cashflows'!AP9 -> 5.8044544 | M37: ='Kirchner EBs Cashflows'!AQ9 -> 12.814665 | ... AQ37: ='Kirchner EBs Cashflows'!BU9 -> 0
B38: XS0501194756 | C38: =C10 -> USD 2033 Discount II and III | F38: =F37 -> 5.8044544 | G38: =G37 -> 5.8044544 | H38: =H37 -> 5.8044544 | I38: =I37 -> 5.8044544 | J38: =J37 -> 5.8044544 | K38: =K37 -> 5.8044544 | L38: =L37 -> 5.8044544 | M38: =M37 -> 12.814665 | ... AQ38: =AQ37 -> 0
B39: US040114GK09 | C39: =C11 -> USD Par 2038 I | F39: ='Kirchner EBs Cashflows'!AJ17 -> 1.875 | G39: ='Kirchner EBs Cashflows'!AK17 -> 1.875 | H39: ='Kirchner EBs Cashflows'!AL17 -> 1.875 | I39: ='Kirchner EBs Cashflows'!AM17 -> 1.875 | J39: ='Kirchner EBs Cashflows'!AN17 -> 1.875 | K39: ='Kirchner EBs Cashflows'!AO17 -> 1.875 | L39: ='Kirchner EBs Cashflows'!AP17 -> 1.875 | M39: ='Kirchner EBs Cashflows'!AQ17 -> 1.875 | ... AQ39: ='Kirchner EBs Cashflows'!BU17 -> 5.065625
B40: XS0501195647 | C40: =C12 -> USD Par 2038 II and III | F40: =F39 -> 1.875 | G40: =G39 -> 1.875 | H40: =H39 -> 1.875 | I40: =I39 -> 1.875 | J40: =J39 -> 1.875 | K40: =K39 -> 1.875 | L40: =L39 -> 1.875 | M40: =M39 -> 1.875 | ... AQ40: =AQ39 -> 5.065625
B41: XS0205545840 | C41: =C13 -> Euro 2033 Discount I | F41: ='Kirchner EBs Cashflows'!AJ27 -> 5.3943902 | G41: ='Kirchner EBs Cashflows'!AK27 -> 5.3943902 | H41: ='Kirchner EBs Cashflows'!AL27 -> 5.3943902 | I41: ='Kirchner EBs Cashflows'!AM27 -> 5.3943902 | J41: ='Kirchner EBs Cashflows'!AN27 -> 5.3943902 | K41: ='Kirchner EBs Cashflows'!AO27 -> 5.3943902 | L41: ='Kirchner EBs Cashflows'!AP27 -> 5.3943902 | M41: ='Kirchner EBs Cashflows'!AQ27 -> 12.292587 | ... AQ41: ='Kirchner EBs Cashflows'!BU27 -> 0
B42: XS0501195134 | C42: =C14 -> Euro 2033 Discount II and III | F42: =F41 -> 5.3943902 | G42: =G41 -> 5.3943902 | H42: =H41 -> 5.3943902 | I42: =I41 -> 5.3943902 | J42: =J41 -> 5.3943902 | K42: =K41 -> 5.3943902 | L42: =L41 -> 5.3943902 | M42: =M41 -> 12.292587 | ... AQ42: =AQ41 -> 0
...

Sheet EBs Prices
GH1: -6 months | JV1: -3 months | KY1: -2 months | ME1: -1 month | MO1: xxx | NJ1: exchange settlement date
D2: (Composite Mid Price)
A3: Short Name | B3: Issue date | C3: ISIN (SEC) | D3: (CMPM) | E3: 43709 | F3: 43710 | G3: 43711 | H3: 43712 | I3: 43713 | J3: 43714 | K3: 43715 | L3: 43716 | M3: 43717 | N3: 43718 | O3: 43719 | P3: 43720 | Q3: 43721 | R3: 43722 | S3: 43723 | T3: 43724 | U3: 43725 | V3: 43726 | W3: 43727 | X3: 43728 | Y3: 43729 | Z3: 43730 | AA3: 43731 | AB3: 43732 | AC3: 43733 | AD3: 43734 | AE3: 43735 | AF3: 43736 | AG3: 43737 | AH3: 43738 | AI3: 43739 | AJ3: 43740 | AK3: 43741 | AL3: 43742 | AM3: 43743 | AN3: 43744 | AO3: 43745 | AP3: 43746 | AQ3: 43747 | AR3: 43748 | AS3: 43749 | AT3: 43750 | AU3: 43751 | AV3: 43752 | AW3: 43753 | AX3: 43754 | AY3: 43755 | AZ3: 43756 | BA3: 43757 | BB3: 43758 | BC3: 43759 | BD3: 43760 | BE3: 43761 | BF3: 43762 | BG3: 43763 | BH3: 43764 | BI3: 43765 | BJ3: 43766 | BK3: 43767 | BL3: 43768 | BM3: 43769 | BN3: 43770 | BO3: 43771 | BP3: 43772 | BQ3: 43773 | BR3: 43774 | BS3: 43775 | BT3: 43776 | BU3: 43777 | BV3: 43778 | BW3: 43779 | BX3: 43780 | BY3: 43781 | BZ3: 43782 | CA3: 43783 | CB3: 43784 | CC3: 43785 | CD3: 43786 | CE3: 43787 | CF3: 43788 | CG3: 43789 | CH3: 43790 | CI3: 43791 | CJ3: 43792 | CK3: 43793 | CL3: 43794 | CM3: 43795 | CN3: 43796 | CO3: 43797 | CP3: 43798 | CQ3: 43799 | CR3: 43800 | CS3: 43801 | CT3: 43802 | CU3: 43803 | CV3: 43804 | CW3: 43805 | CX3: 43806 | CY3: 43807 | CZ3: 43808 | DA3: 43809 | DB3: 43810 | DC3: 43811 | DD3: 43812 | DE3: 43813 | DF3: 43814 | DG3: 43815 | DH3: 43816 | DI3: 43817 | DJ3: 43818 | DK3: 43819 | DL3: 43820 | DM3: 43821 | DN3: 43822 | DO3: 43823 | DP3: 43824 | DQ3: 43825 | DR3: 43826 | DS3: 43827 | DT3: 43828 | DU3: 43829 | DV3: 43830 | DW3: 43831 | DX3: 43832 | DY3: 43833 | DZ3: 43834 | EA3: 43835 | EB3: 43836 | EC3: 43837 | ED3: 43838 | EE3: 43839 | EF3: 43840 | EG3: 43841 | EH3: 43842 | EI3: 43843 | EJ3: 43844 | EK3: 43845 | EL3: 43846 | EM3: 43847 | EN3: 43848 | EO3: 43849 | EP3: 43850 | EQ3: 43851 | ER3: 43852 | ES3: 43853 | ET3: 43854 | EU3: 43855 | EV3: 43856 | EW3: 43857 | EX3: 43858 | EY3: 43859 | EZ3: 43860 | FA3: 43861 | FB3: 43862 | FC3: 43863 | FD3: 43864 | FE3: 43865 | FF3: 43866 | FG3: 43867 | FH3: 43868 | FI3: 43869 | FJ3: 43870 | FK3: 43871 | FL3: 43872 | FM3: 43873 | FN3: 43874 | FO3: 43875 | FP3: 43876 | FQ3: 43877 | FR3: 43878 | FS3: 43879 | FT3: 43880 | FU3: 43881 | FV3: 43882 | FW3: 43883 | FX3: 43884 | FY3: 43885 | FZ3: 43886 | GA3: 43887 | GB3: 43888 | GC3: 43889 | GD3: 43890 | GE3: 43891 | GF3: 43892 | GG3: 43893 | GH3: 43894 | GI3: 43895 | GJ3: 43896 | GK3: 43897 | GL3: 43898 | GM3: 43899 | GN3: 43900 | GO3: 43901 | GP3: 43902 | GQ3: 43903 | GR3: 43904 | GS3: 43905 | GT3: 43906 | GU3: 43907 | GV3: 43908 | GW3: 43909 | GX3: 43910 | GY3: 43911 | GZ3: 43912 | HA3: 43913 | HB3: 43914 | HC3: 43915 | HD3: 43916 | HE3: 43917 | HF3: 43918 | HG3: 43919 | HH3: 43920 | HI3: 43921 | HJ3: 43922 | HK3: 43923 | HL3: 43924 | HM3: 43925 | HN3: 43926 | HO3: 43927 | HP3: 43928 | HQ3: 43929 | HR3: 43930 | HS3: 43931 | HT3: 43932 | HU3: 43933 | HV3: 43934 | HW3: 43935 | HX3: 43936 | HY3: 43937 | HZ3: 43938 | IA3: 43939 | IB3: 43940 | IC3: 43941 | ID3: 43942 | IE3: 43943 | IF3: 43944 | IG3: 43945 | IH3: 43946 | II3: 43947 | IJ3: 43948 | IK3: 43949 | IL3: 43950 | IM3: 43951 | IN3: 43952 | IO3: 43953 | IP3: 43954 | IQ3: 43955 | IR3: 43956 | IS3: 43957 | IT3: 43958 | IU3: 43959 | IV3: 43960 | IW3: 43961 | IX3: 43962 | IY3: 43963 | IZ3: 43964 | JA3: 43965 | JB3: 43966 | JC3: 43967 | JD3: 43968 | JE3: 43969 | JF3: 43970 | JG3: 43971 | JH3: 43972 | JI3: 43973 | JJ3: 43974 | JK3: 43975 | JL3: 43976 | JM3: 43977 | JN3: 43978 | JO3: 43979 | JP3: 43980 | JQ3: 43981 | JR3: 43982 | JS3: 43983 | JT3: 43984 | JU3: 43985 | JV3: 43986 | JW3: 43987 | JX3: 43988 | JY3: 43989 | JZ3: 43990 | KA3: 43991 | KB3: 43992 | KC3: 43993 | KD3: 43994 | KE3: 43995 | KF3: 43996 | KG3: 43997 | KH3: 43998 | KI3: 43999 | KJ3: 44000 | KK3: 44001 | KL3: 44002 | KM3: 44003 | KN3: 44004 | KO3: 44005 | KP3: 44006 | KQ3: 44007 | KR3: 44008 | KS3: 44009 | KT3: 44010 | KU3: 44011 | KV3: 44012 | KW3: 44013 | KX3: 44014 | KY3: 44015 | KZ3: 44016 | LA3: 44017 | LB3: 44018 | LC3: 44019 | LD3: 44020 | LE3: 44021 | LF3: 44022 | LG3: 44023 | LH3: 44024 | LI3: 44025 | LJ3: 44026 | LK3: 44027 | LL3: 44028 | LM3: 44029 | LN3: 44030 | LO3: 44031 | LP3: 44032 | LQ3: 44033 | LR3: 44034 | LS3: 44035 | LT3: 44036 | LU3: 44037 | LV3: 44038 | LW3: 44039 | LX3: 44040 | LY3: 44041 | LZ3: 44042 | MA3: 44043 | MB3: 44044 | MC3: 44045 | MD3: 44046 | ME3: 44047 | MF3: 44048 | MG3: 44049 | MH3: 44050 | MI3: 44051 | MJ3: 44052 | MK3: 44053 | ML3: 44054 | MM3: 44055 | MN3: 44056 | MO3: 44057 | MP3: 44058 | MQ3: 44059 | MR3: 44060 | MS3: 44061 | MT3: 44062 | MU3: 44063 | MV3: 44064 | MW3: 44065 | MX3: 44066 | MY3: 44067 | MZ3: 44068 | NA3: 44069 | NB3: 44070 | NC3: 44071 | ND3: 44072 | NE3: 44073 | NF3: 44074 | NG3: 44075 | NH3: 44076 | NI3: 44077 | NJ3: 44078 | NK3: 44079 | NL3: 44080 | NM3: 44081 | NN3: 44082 | NO3: 44083 | NP3: 44084 | NQ3: 44085 | NR3: 44086 | NS3: 44087 | NT3: 44088 | NU3: 44089 | NV3: 44090 | NW3: 44091 | NX3: 44092 | NY3: 44093 | NZ3: 44094 | OA3: 44095 | OB3: 44096 | OC3: 44097 | OD3: 44098 | OE3: 44099 | OF3: 44100 | OG3: 44101 | OH3: 44102 | OI3: 44103 | OJ3: 44104 | OK3: 44105 | OL3: 44106 | OM3: 44107 | ON3: 44108 | OO3: 44109 | OP3: 44110 | OQ3: 44111 | OR3: 44112 | OS3: 44113 | OT3: 44114 | OU3: 44115 | OV3: 44116 | OW3: 44117 | OX3: 44118 | OY3: 44119 | OZ3: 44120 | PA3: 44121 | PB3: 44122 | PC3: 44123 | PD3: 44124 | PE3: 44125 | PF3: 44126 | PG3: 44127 | PH3: 44128 | PI3: 44129 | PJ3: 44130 | PK3: 44131 | PL3: 44132 | PM3: 44133 | PN3: 44134 | PO3: 44135 | PP3: 44136 | PQ3: 44137 | PR3: 44138 | PS3: 44139 | PT3: 44140 | PU3: 44141 | PV3: 44142 | PW3: 44143 | PX3: 44144 | PY3: 44145 | PZ3: 44146 | QA3: 44147 | QB3: 44148 | QC3: 44149 | QD3: 44150 | QE3: 44151 | QF3: 44152 | QG3: 44153 | QH3: 44154 | QI3: 44155 | QJ3: 44156 | QK3: 44157 | QL3: 44158 | QM3: 44159 | QN3: 44160 | QO3: 44161
A4: USD 2033 Discount I | B4: 38626 | C4: US040114GL81 | F4: 41.5 | G4: 41.4375 | H4: 44.3125 | I4: 46 | J4: 48.5 | M4: 50.2745 | N4: 48.4375 | O4: 48.625 | P4: 48 | Q4: 47.4175 | T4: 46.6945 | U4: 47.5245 | V4: 48.761 | W4: 48.4375 | X4: 49.125 | AA4: 48.4375 | AB4: 48 | AC4: 47.7115 | AD4: 48.25 | AE4: 49.375 | AH4: 49.6875 | AI4: 49.5625 | AJ4: 49.6875 | AK4: 49.9375 | AL4: 50.4375 | AO4: 51.375 | AP4: 51.128 | AQ4: 52.625 | AR4: 54 | AS4: 55 | AV4: 55.415 | AW4: 55.75 | AX4: 54.75 | AY4: 55.5 | AZ4: 54.5 | BC4: 53.125 | BD4: 52.3125 | BE4: 52.75 | BF4: 53.825 | BG4: 53.016 | BJ4: 51.25 | BK4: 51.58 | BL4: 51 | BM4: 51.3675 | BN4: 51.572 | BQ4: 51.475 | BR4: 51.241 | BS4: 51.355 | BT4: 50.5 | BU4: 48.91 | BX4: 49.0625 | BY4: 46.6875 | BZ4: 46.8125 | CA4: 47.64 | CB4: 46.375 | CE4: 47.12 | CF4: 48.5625 | CG4: 49 | CH4: 50.25 | CI4: 50 | CL4: 48.5 | CM4: 49.625 | CN4: 49.511 | CO4: 49.75 | CP4: 49.648 | CS4: 49 | CT4: 47.86 | CU4: 48.75 | CV4: 48.625 | CW4: 49 | CZ4: 51.03 | DA4: 51.5 | DB4: 51.717 | DC4: 53.375 | DD4: 53.3125 | DG4: 53.625 | DH4: 56.0625 | DI4: 58.0625 | DJ4: 57.4375 | DK4: 56.75 | DN4: 58.252 | DO4: 57.75 | DP4: 57.75 | DQ4: 57.75 | DR4: 62.775 | DU4: 61.0225 | DV4: 61.125 | DW4: 61.125 | DX4: 61.375 | DY4: 61.495 | EB4: 59 | EC4: 60.95 | ED4: 62 | EE4: 62.5 | EF4: 62.27 | EI4: 62.375 | EJ4: 62.0305 | EK4: 61.75 | EL4: 63 | EM4: 61.993 | EP4: 61.5 | EQ4: 60.0625 | ER4: 59.0265 | ES4: 58.5 | ET4: 57.7595 | EW4: 55.125 | EX4: 55.111 | EY4: 55.875 | EZ4: 56.125 | FA4: 56 | FD4: 56.625 | FE4: 58.4465 | FF4: 59.25 | FG4: 59 | FH4: 60.1875 | FK4: 60.125 | FL4: 58.0625 | FM4: 58.857 | FN4: 58 | FO4: 57.8125 | FR4: 57.6975 | FS4: 57.5 | FT4: 57.5165 | FU4: 56.5 | FV4: 56.6215 | FY4: 57 | FZ4: 56.8195 | GA4: 57 | GB4: 56.8035 | GC4: 53.9375 | GF4: 54.1875 | GG4: 55.0625 | GH4: 55.25 | GI4: 54.5 | GJ4: 50.6875 | GM4: 51.197 | GN4: 45.5 | GO4: 44.6475 | GP4: 40.625 | GQ4: 40.4375 | GT4: 39.5665 | GU4: 38.25 | GV4: 37.48 | GW4: 34.25 | GX4: 34.5 | HA4: 33.875 | HB4: 33.702 | HC4: 32.8835 | HD4: 33.125 | HE4: 34.04 | HH4: 34.3195 | HI4: 34.5 | HJ4: 35.5425 | HK4: 35.909 | HL4: 37.0305 | HO4: 38.164 | HP4: 37.25 | HQ4: 36.625 | HR4: 37.4445 | HS4: 36.375 | HV4: 36.75 | HW4: 36.25 | HX4: 35.75 | HY4: 35.5 | HZ4: 36.125 | IC4: 36.9925 | ID4: 37.396 | IE4: 36.375 | IF4: 34.875 | IG4: 34.5 | IJ4: 35.125 | IK4: 35.812 | IL4: 36.859 | IM4: 35.375 | IN4: 34.5 | IQ4: 33.25 | IR4: 33 | IS4: 33.25 | IT4: 33.5 | IU4: 34.375 | IX4: 35 | IY4: 38.125 | IZ4: 37.5 | JA4: 37.4635 | JB4: 39.9685 | JE4: 41.163 | JF4: 42.2085 | JG4: 42.687 | JH4: 42 | JI4: 41.7935 | JL4: 41.355 | JM4: 41.449 | JN4: 41.449 | JO4: 45.295 | JP4: 45.3995 | JS4: 45.3995 | JT4: 46.25 | JU4: 48.094 | JV4: 48.375 | JW4: 48.125 | JZ4: 47.75 | KA4: 47.9075 | KB4: 46.5 | KC4: 46 | KD4: 46 | KG4: 45.375 | KH4: 46.125 | KI4: 45.8075 | KJ4: 44.848 | KK4: 46 | KN4: 46.125 | KO4: 46.875 | KP4: 45.875 | KQ4: 45.8595 | KR4: 45.25 | KU4: 45.774 | KV4: 45.25 | KW4: 44.875 | KX4: 45.5 | KY4: 45.5 | LB4: 47.5 | LC4: 48 | LD4: 49.375 | LE4: 48.375 | LF4: 48.875 | LI4: 49.24 | LJ4: 48.631 | LK4: 48.875 | LL4: 49.625 | LM4: 49.625 | LP4: 49.6305 | LQ4: 49.75 | LR4: 50.375 | LS4: 51.985 | LT4: 51.4875 | LW4: 51.25 | LX4: 50.75 | LY4: 49.875 | LZ4: 50.5 | MA4: 51 | MD4: 50.955 | ME4: 54.875 | MF4: 54.974 | MG4: 54.875 | MH4: 55.125 | MK4: 53.5 | ML4: 54.5 | MM4: 54.75 | MN4: 54.5515 | MO4: 53.875 | MR4: 53.5 | MS4: 53.375 | MT4: 53.167 | MU4: 52.75 | MV4: 53.0385 | MY4: 53.0435 | MZ4: 52.86 | NA4: 49.94 | NB4: 49.94 | NC4: 49.94 | NF4: 51.38 | NG4: 51.145 | NH4: 51.145 | NI4: 51.145 | NJ4: 51.145
A5: USD 2033 Discount II and III | B5: 40296 | C5: XS0501194756 | F5: 39.75 | G5: 39.75 | H5: 39.75 | I5: 44 | J5: 45.5 | M5: 49.5 | N5: 45 | O5: 47.25 | P5: 48 | Q5: 48 | T5: 45.5 | U5: 45.5 | V5: 47.5 | W5: 47.5 | X5: 47.5 | AA5: 47.5 | AB5: 46.75 | AC5: 46.75 | AD5: 48.125 | AE5: 48 | AH5: 49.125 | AI5: 48.5 | AJ5: 49.5 | AK5: 49.5 | AL5: 49.5 | AO5: 49.5 | AP5: 49.5 | AQ5: 49.5 | AR5: 49.5 | AS5: 49.5 | AV5: 49.5 | AW5: 49.5 | AX5: 49.5 | AY5: 49.5 | AZ5: 49.5 | BC5: 49.5 | BD5: 52.25 | BE5: 52.625 | BF5: 53.5 | BG5: 52.125 | BJ5: 51.5 | BK5: 50.375 | BL5: 51 | BM5: 51 | BN5: 50.5 | BQ5: 50.5 | BR5: 50.5 | BS5: 50 | BT5: 50.5 | BU5: 50.5 | BX5: 50.5 | BY5: 50.5 | BZ5: 50.5 | CA5: 50.5 | CB5: 50.5 | CE5: 50.5 | CF5: 50.5 | CG5: 50.5 | CH5: 50.5 | CI5: 50.5 | CL5: 50.5 | CM5: 50.5 | CN5: 50.5 | CO5: 50.5 | CP5: 50.5 | CS5: 50.5 | CT5: 50.5 | CU5: 50.5 | CV5: 50.5 | CW5: 50.5 | CZ5: 50.5 | DA5: 50.5 | DB5: 50.5 | DC5: 50.5 | DD5: 50.5 | DG5: 50.5 | DH5: 50.5 | DI5: 50.5 | DJ5: 50.5 | DK5: 50.5 | DN5: 57.75 | DO5: 57.75 | DP5: 56.75 | DQ5: 59.25 | DR5: 60.625 | DU5: 61.125 | DV5: 61.125 | DW5: 61.125 | DX5: 61.375 | DY5: 59.75 | EB5: 59 | EC5: 58.5 | ED5: 60.25 | EE5: 61.5 | EF5: 62.5 | EI5: 62.375 | EJ5: 59.25 | EK5: 61.5 | EL5: 62.25 | EM5: 60.5 | EP5: 61.25 | EQ5: 59.375 | ER5: 58.25 | ES5: 57.875 | ET5: 56.75 | EW5: 55 | EX5: 55.125 | EY5: 55.875 | EZ5: 55.25 | FA5: 55.25 | FD5: 56.25 | FE5: 57 | FF5: 58.75 | FG5: 58.5 | FH5: 59.625 | FK5: 59.5 | FL5: 59.25 | FM5: 58.5 | FN5: 57.125 | FO5: 57.375 | FR5: 58.375 | FS5: 57.25 | FT5: 57.375 | FU5: 56 | FV5: 57.375 | FY5: 56.75 | FZ5: 56 | GA5: 56.75 | GB5: 54.25 | GC5: 53.625 | GF5: 53.5 | GG5: 54.75 | GH5: 54.5 | GI5: 53.125 | GJ5: 50.875 | GM5: 46 | GN5: 44.75 | GO5: 42.25 | GP5: 40.375 | GQ5: 40.125 | GT5: 36.25 | GU5: 37.25 | GV5: 34.125 | GW5: 34.25 | GX5: 34.5 | HA5: 31.25 | HB5: 30.875 | HC5: 32.25 | HD5: 33.125 | HE5: 33.375 | HH5: 33.5 | HI5: 34.5 | HJ5: 34.375 | HK5: 35.25 | HL5: 35.625 | HO5: 37.5 | HP5: 37.25 | HQ5: 36.625 | HR5: 36.375 | HS5: 36.375 | HV5: 36.75 | HW5: 35.5 | HX5: 35.75 | HY5: 34.5 | HZ5: 34.25 | IC5: 34.25 | ID5: 37.875 | IE5: 36.375 | IF5: 34.875 | IG5: 34.5 | IJ5: 34.875 | IK5: 35.375 | IL5: 35.75 | IM5: 35.375 | IN5: 33.5 | IQ5: 31.5 | IR5: 33 | IS5: 33.875 | IT5: 34.875 | IU5: 34.375 | IX5: 36.625 | IY5: 38.125 | IZ5: 37.5 | JA5: 37 | JB5: 38.125 | JE5: 40.125 | JF5: 40.75 | JG5: 40.625 | JH5: 42 | JI5: 41.875 | JL5: 41.875 | JM5: 45 | JN5: 44.75 | JO5: 44 | JP5: 46.375 | JS5: 46.125 | JT5: 46.25 | JU5: 46.625 | JV5: 46.5 | JW5: 48.125 | JZ5: 47.75 | KA5: 44.875 | KB5: 46.5 | KC5: 46 | KD5: 46 | KG5: 45.375 | KH5: 46.125 | KI5: 46 | KJ5: 45 | KK5: 46 | KN5: 46.125 | KO5: 46.875 | KP5: 45.75 | KQ5: 45.75 | KR5: 45.25 | KU5: 44.125 | KV5: 45.25 | KW5: 45.375 | KX5: 45.5 | KY5: 45.5 | LB5: 47.5 | LC5: 48 | LD5: 49.375 | LE5: 48.375 | LF5: 48.875 | LI5: 48.875 | LJ5: 48.875 | LK5: 48.875 | LL5: 49.625 | LM5: 49.625 | LP5: 49.5 | LQ5: 49.75 | LR5: 50.375 | LS5: 51.375 | LT5: 51.625 | LW5: 51.25 | LX5: 50.75 | LY5: 49.875 | LZ5: 50.5 | MA5: 51 | MD5: 50.625 | ME5: 54.875 | MF5: 54.625 | MG5: 54.875 | MH5: 52.75 | MK5: 52.375 | ML5: 54.5 | MM5: 54.75 | MN5: 52 | MO5: 53.875 | MR5: 53.5 | MS5: 53.375 | MT5: 53.125 | MU5: 52.75 | MV5: 52.75 | MY5: 52.75 | MZ5: 52.75 | NA5: 53 | NB5: 50.25 | NC5: 52.5 | NF5: 52.625 | NG5: 53.75 | NH5: 52.125 | NI5: 50.75 | NJ5: 50.5
A6: USD 2033 Discount III | B6: 40296 | C6: XS0501195050 | F6: 38.25 | G6: 38.5 | H6: 40 | I6: 43.25 | J6: 46.25 | M6: 47 | N6: 45.25 | O6: 46.75 | P6: 47.75 | Q6: 47.75 | T6: 47.75 | U6: 47.75 | V6: 47.25 | W6: 47.25 | X6: 47.25 | AA6: 47.25 | AB6: 47.25 | AC6: 47.25 | AD6: 47.25 | AE6: 47.25 | AH6: 48.875 | AI6: 48.25 | AJ6: 48.75 | AK6: 48.75 | AL6: 48.75 | AO6: 48.75 | AP6: 48.75 | AQ6: 48.75 | AR6: 48.75 | AS6: 48.75 | AV6: 48.75 | AW6: 48.75 | AX6: 48.75 | AY6: 48.75 | AZ6: 48.75 | BC6: 48.75 | BD6: 52 | BE6: 52.375 | BF6: 53.375 | BG6: 51.875 | BJ6: 51.25 | BK6: 51.25 | BL6: 50.75 | BM6: 50.75 | BN6: 51 | BQ6: 51 | BR6: 51 | BS6: 51 | BT6: 50.25 | BU6: 50.5 | BX6: 50.5 | BY6: 50.5 | BZ6: 50.5 | CA6: 50.5 | CB6: 50.5 | CE6: 50.5 | CF6: 50.5 | CG6: 50.5 | CH6: 50.5 | CI6: 50.5 | CL6: 50.5 | CM6: 50.5 | CN6: 48.5 | CO6: 48.5 | CP6: 48.5 | CS6: 48.5 | CT6: 48.5 | CU6: 48.5 | CV6: 48.5 | CW6: 48.5 | CZ6: 48.5 | DA6: 48.5 | DB6: 48.5 | DC6: 48.5 | DD6: 48.5 | DG6: 48.5 | DH6: 48.5 | DI6: 48.5 | DJ6: 48.5 | DK6: 48.5 | DN6: 57.5 | DO6: 57.5 | DP6: 56.5 | DQ6: 59 | DR6: 60.375 | DU6: 60.875 | DV6: 60.875 | DW6: 60.875 | DX6: 61.125 | DY6: 59.5 | EB6: 58.75 | EC6: 58.25 | ED6: 60.5 | EE6: 61.25 | EF6: 62.25 | EI6: 62.125 | EJ6: 59 | EK6: 61.25 | EL6: 62 | EM6: 60.25 | EP6: 61 | EQ6: 59.125 | ER6: 58 | ES6: 57.625 | ET6: 56.5 | EW6: 54.75 | EX6: 54.875 | EY6: 55.625 | EZ6: 55 | FA6: 55 | FD6: 56 | FE6: 56.75 | FF6: 58.5 | FG6: 58.25 | FH6: 59.375 | FK6: 59.25 | FL6: 59 | FM6: 58.25 | FN6: 56.875 | FO6: 57.125 | FR6: 58.125 | FS6: 57 | FT6: 57.125 | FU6: 55.75 | FV6: 57.125 | FY6: 56.5 | FZ6: 55.75 | GA6: 56.5 | GB6: 54 | GC6: 53.375 | GF6: 53.25 | GG6: 54.5 | GH6: 54.25 | GI6: 52.875 | GJ6: 50.625 | GM6: 45.75 | GN6: 44.5 | GO6: 42 | GP6: 40.125 | GQ6: 39.875 | GT6: 36 | GU6: 37 | GV6: 33.875 | GW6: 34 | GX6: 34.25 | HA6: 31 | HB6: 30.625 | HC6: 32 | HD6: 32.875 | HE6: 33.125 | HH6: 33.25 | HI6: 34.25 | HJ6: 34.125 | HK6: 35 | HL6: 35.375 | HO6: 37.25 | HP6: 37 | HQ6: 36.375 | HR6: 36.125 | HS6: 36.125 | HV6: 36.5 | HW6: 35.25 | HX6: 35.5 | HY6: 34.25 | HZ6: 34 | IC6: 34 | ID6: 37.625 | IE6: 36.125 | IF6: 34.625 | IG6: 34.25 | IJ6: 34.625 | IK6: 35.125 | IL6: 35.5 | IM6: 35.125 | IN6: 33.25 | IQ6: 31.25 | IR6: 32.75 | IS6: 33.625 | IT6: 34.625 | IU6: 34.125 | IX6: 36.375 | IY6: 37.875 | IZ6: 37.25 | JA6: 36.75 | JB6: 37.875 | JE6: 39.875 | JF6: 40.5 | JG6: 40.375 | JH6: 41.75 | JI6: 41.625 | JL6: 41.625 | JM6: 44.75 | JN6: 44.5 | JO6: 43.75 | JP6: 46.125 | JS6: 45.875 | JT6: 46 | JU6: 46.375 | JV6: 46.25 | JW6: 47.875 | JZ6: 47.5 | KA6: 44.625 | KB6: 46.25 | KC6: 45.75 | KD6: 45.75 | KG6: 45.125 | KH6: 45.875 | KI6: 45.75 | KJ6: 44.75 | KK6: 45.75 | KN6: 45.875 | KO6: 46.625 | KP6: 45.5 | KQ6: 45.375 | KR6: 45 | KU6: 43.625 | KV6: 45 | KW6: 44.625 | KX6: 45.25 | KY6: 45.25 | LB6: 47.25 | LC6: 47.75 | LD6: 49.125 | LE6: 48.125 | LF6: 48.625 | LI6: 48.625 | LJ6: 48.625 | LK6: 48.625 | LL6: 49.375 | LM6: 49.375 | LP6: 49.25 | LQ6: 49.5 | LR6: 50.125 | LS6: 51.125 | LT6: 51.375 | LW6: 51 | LX6: 50.5 | LY6: 49.625 | LZ6: 50.25 | MA6: 50.75 | MD6: 50.375 | ME6: 54.625 | MF6: 54.375 | MG6: 54.625 | MH6: 52.5 | MK6: 52.125 | ML6: 54.25 | MM6: 54.5 | MN6: 51.75 | MO6: 53.625 | MR6: 53.25 | MS6: 53.125 | MT6: 52.875 | MU6: 52.5 | MV6: 52.5 | MY6: 52.5 | MZ6: 52.5 | NA6: 52.75 | NB6: 50 | NC6: 52.25 | NF6: 52.375 | NG6: 53.5 | NH6: 51.875 | NI6: 50.5 | NJ6: 50.25
